Workbook

Sheet Products
A1: 📦 PRODUCT MASTER DATABASE
A2: Electronics Shop — Product Catalog & Pricing
A3: Product ID | B3: Product Name | C3: Category | D3: Brand | E3: Unit | F3: Cost Price | G3: Selling Price | H3: Reorder Level | I3: Supplier ID | J3: Description | K3: Status
A4: P001 | B4: Samsung Galaxy S24 | C4: Mobile Phones | D4: Samsung | E4: Unit | F4: 85000 | G4: 110000 | H4: 5 | I4: SUP001 | J4: Flagship smartphone 256GB | K4: Active
A5: P002 | B5: iPhone 15 Pro | C5: Mobile Phones | D5: Apple | E5: Unit | F5: 195000 | G5: 240000 | H5: 3 | I5: SUP002 | J5: Apple A17 Pro chip 256GB | K5: Active
A6: P003 | B6: Xiaomi Redmi Note 13 | C6: Mobile Phones | D6: Xiaomi | E6: Unit | F6: 35000 | G6: 45000 | H6: 10 | I6: SUP003 | J6: 6.67 inch AMOLED display | K6: Active
A7: P004 | B7: Samsung 55" 4K TV | C7: Televisions | D7: Samsung | E7: Unit | F7: 95000 | G7: 125000 | H7: 3 | I7: SUP001 | J7: Crystal UHD Smart TV | K7: Active
A8: P005 | B8: Sony Bravia 43" | C8: Televisions | D8: Sony | E8: Unit | F8: 85000 | G8: 110000 | H8: 3 | I8: SUP004 | J8: Google TV X80L | K8: Active
A9: P006 | B9: LG 32" Full HD | C9: Televisions | D9: LG | E9: Unit | F9: 42000 | G9: 58000 | H9: 5 | I9: SUP005 | J9: IPS Panel Smart TV | K9: Active
A10: P007 | B10: Dell Inspiron 15 | C10: Laptops | D10: Dell | E10: Unit | F10: 78000 | G10: 99000 | H10: 4 | I10: SUP006 | J10: Intel i5 12th Gen 8GB RAM | K10: Active
A11: P008 | B11: HP Pavilion 14 | C11: Laptops | D11: HP | E11: Unit | F11: 72000 | G11: 92000 | H11: 4 | I11: SUP006 | J11: Ryzen 5 16GB RAM | K11: Active
A12: P009 | B12: Lenovo IdeaPad 5 | C12: Laptops | D12: Lenovo | E12: Unit | F12: 68000 | G12: 88000 | H12: 5 | I12: SUP007 | J12: Intel i5 512GB SSD | K12: Active
A13: P010 | B13: MacBook Air M2 | C13: Laptops | D13: Apple | E13: Unit | F13: 185000 | G13: 225000 | H13: 2 | I13: SUP002 | J13: 8GB 256GB SSD | K13: Active
A14: P011 | B14: Samsung Galaxy Tab S9 | C14: Tablets | D14: Samsung | E14: Unit | F14: 95000 | G14: 120000 | H14: 3 | I14: SUP001 | J14: 11" AMOLED 256GB | K14: Active
A15: P012 | B15: iPad Air 5th Gen | C15: Tablets | D15: Apple | E15: Unit | F15: 120000 | G15: 150000 | H15: 3 | I15: SUP002 | J15: 10.9" Liquid Retina | K15: Active
... A28: P025 | B28: Canon EOS R50 | C28: Cameras | D28: Canon | E28: Unit | F28: 125000 | G28: 160000 | H28: 2 | I28: SUP015 | J28: 24.2MP Mirrorless | K28: Active

Sheet Suppliers
A1: 🏭 SUPPLIER MASTER DATABASE
A2: Vendor Information & Payment Terms
A3: Supplier ID | B3: Supplier Name | C3: Contact Person | D3: Phone | E3: Email | F3: City | G3: Payment Terms | H3: Credit Limit | I3: Status
A4: SUP001 | B4: Samsung Pakistan | C4: Ali Hassan | D4: 0300-1234567 | E4: ali@samsung.pk | F4: Karachi | G4: 30 Days | H4: 5000000 | I4: Active
A5: SUP002 | B5: Apple Authorized Dist. | C5: Sara Khan | D5: 0321-9876543 | E5: sara@appledist.pk | F5: Lahore | G5: 45 Days | H5: 8000000 | I5: Active
A6: SUP003 | B6: Xiaomi Pakistan | C6: Usman Malik | D6: 0333-5555555 | E6: usman@xiaomi.pk | F6: Karachi | G6: 30 Days | H6: 3000000 | I6: Active
A7: SUP004 | B7: Sony Pakistan | C7: Fatima Zaidi | D7: 0312-4444444 | E7: fatima@sony.pk | F7: Islamabad | G7: 30 Days | H7: 4000000 | I7: Active
A8: SUP005 | B8: LG Electronics | C8: Tariq Mehmood | D8: 0345-7777777 | E8: tariq@lgelec.pk | F8: Karachi | G8: 45 Days | H8: 3500000 | I8: Active
A9: SUP006 | B9: Dell & HP Distributor | C9: Zara Ahmed | D9: 0311-2222222 | E9: zara@dellhp.pk | F9: Lahore | G9: 30 Days | H9: 4500000 | I9: Active
A10: SUP007 | B10: Lenovo Distributor | C10: Bilal Raza | D10: 0322-3333333 | E10: bilal@lenovo.pk | F10: Karachi | G10: 30 Days | H10: 3000000 | I10: Active
A11: SUP008 | B11: Haier Pakistan | C11: Nadia Siddiqui | D11: 0323-6666666 | E11: nadia@haier.pk | F11: Lahore | G11: 45 Days | H11: 2500000 | I11: Active
A12: SUP009 | B12: Dawlance/PEL Dealer | C12: Kamran Iqbal | D12: 0334-8888888 | E12: kamran@dawlance.pk | F12: Karachi | G12: 30 Days | H12: 2000000 | I12: Active
A13: SUP010 | B13: JBL Audio Pakistan | C13: Aisha Farooq | D13: 0335-9999999 | E13: aisha@jbl.pk | F13: Islamabad | G13: 30 Days | H13: 1500000 | I13: Active
A14: SUP011 | B14: TP-Link Pakistan | C14: Hasan Raza | D14: 0341-1111111 | E14: hasan@tplink.pk | F14: Karachi | G14: 30 Days | H14: 1000000 | I14: Active
A15: SUP012 | B15: Huawei Pakistan | C15: Mariam Shah | D15: 0315-0000000 | E15: mariam@huawei.pk | F15: Lahore | G15: 45 Days | H15: 2000000 | I15: Active
... A18: SUP015 | B18: Canon Pakistan | C18: Rizwan Ali | D18: 0318-6767676 | E18: rizwan@canon.pk | F18: Lahore | G18: 45 Days | H18: 3000000 | I18: Active

Sheet Dashboard
A1: 🏪 ELECTRONICS SHOP — RETAIL MANAGEMENT SYSTEM
A2: Executive Dashboard | Powered by Automated ERP Formulas | Auto-refreshes with data entry
A4: 💰 TOTAL SALES REVENUE | D4: 📦 TOTAL PURCHASES | G4: 📈 GROSS PROFIT | J4: 💵 NET PROFIT
A5: =SUM(Sales!K4:K53) -> 13689270 | D5: =SUM(Purchases!I4:I53) -> 26453500 | G5: ='Profit Analysis'!C16 -> 2241270 | J5: ='Profit Analysis'!C30 -> 52990
A6: All invoices YTD | D6: Stock value procured | G6: Revenue − COGS | J6: After all expenses
A8: 💳 RECEIVABLES DUE | D8: 🏦 PAYABLES DUE | G8: 🏪 INVENTORY VALUE | J8: 💸 TOTAL EXPENSES
A9: =SUM(Receivables!G4:G25) -> 3884191 | D9: =SUM(Payables!G4:G25) -> 4724000 | G9: =SUM(Inventory!K4:K28) -> 45410500 | J9: =SUM(Expenses!E4:E53) -> 2188280
A10: From credit customers | D10: To suppliers | G10: FIFO-based valuation | J10: Operating costs YTD
A13: 📊 SALES BY CATEGORY | G13: 🔴 LOW STOCK ALERTS
A14: Category | B14: Items Sold | C14: Revenue (PKR) | D14: Share % | G14: Product | J14: Stock | K14: Reorder | L14: Alert
A15: Mobile Phones | B15: =SUMIF(Sales!E4:E53,"P001",Sales!G4:G53)+SUMIF(Sales!E4:E53,"P002",Sales!G4:G53)+SUMIF(Sales!E4:E53,"P003",Sales!G4:G53) -> 17 | C15: =SUMIF(Sales!E4:E53,"P001",Sales!K4:K53)+SUMIF(Sales!E4:E53,"P002",Sales!K4:K53)+SUMIF(Sales!E4:E53,"P003",Sales!K4:K53) -> 3001050 | D15: =C15/SUM(Sales!K4:K53) -> 0.21922645 | G15: Samsung Galaxy S24 | J15: =INDEX(Inventory!G4:G28,MATCH("P001",Inventory!A4:A28,0)) -> 45 | K15: 5 | L15: =IF(J15<=K15,"🔴 REORDER","✅ OK") -> ✅ OK
A16: Televisions | B16: =SUMIF(Sales!E4:E53,"P004",Sales!G4:G53)+SUMIF(Sales!E4:E53,"P005",Sales!G4:G53)+SUMIF(Sales!E4:E53,"P006",Sales!G4:G53) -> 14 | C16: =SUMIF(Sales!E4:E53,"P004",Sales!K4:K53)+SUMIF(Sales!E4:E53,"P005",Sales!K4:K53)+SUMIF(Sales!E4:E53,"P006",Sales!K4:K53) -> 1359690 | D16: =C16/SUM(Sales!K4:K53) -> 0.099325238 | G16: iPhone 15 Pro | J16: =INDEX(Inventory!G4:G28,MATCH("P002",Inventory!A4:A28,0)) -> 18 | K16: 3 | L16: =IF(J16<=K16,"🔴 REORDER","✅ OK") -> ✅ OK
A17: Laptops | B17: =SUMIF(Sales!E4:E53,"P007",Sales!G4:G53)+SUMIF(Sales!E4:E53,"P008",Sales!G4:G53)+SUMIF(Sales!E4:E53,"P009",Sales!G4:G53)+SUMIF(Sales!E4:E53,"P010",Sales!G4:G53) -> 43 | C17: =SUMIF(Sales!E4:E53,"P007",Sales!K4:K53)+SUMIF(Sales!E4:E53,"P008",Sales!K4:K53)+SUMIF(Sales!E4:E53,"P009",Sales!K4:K53)+SUMIF(Sales!E4:E53,"P010",Sales!K4:K53) -> 5555680 | D17: =C17/SUM(Sales!K4:K53) -> 0.40584195 | G17: Xiaomi Redmi Note 13 | J17: =INDEX(Inventory!G4:G28,MATCH("P003",Inventory!A4:A28,0)) -> 10 | K17: 10 | L17: =IF(J17<=K17,"🔴 REORDER","✅ OK") -> 🔴 REORDER
A18: Tablets | B18: =SUMIF(Sales!E4:E53,"P011",Sales!G4:G53)+SUMIF(Sales!E4:E53,"P012",Sales!G4:G53) -> 6 | C18: =SUMIF(Sales!E4:E53,"P011",Sales!K4:K53)+SUMIF(Sales!E4:E53,"P012",Sales!K4:K53) -> 648000 | D18: =C18/SUM(Sales!K4:K53) -> 0.047336344 | G18: Samsung 55" 4K TV | J18: =INDEX(Inventory!G4:G28,MATCH("P004",Inventory!A4:A28,0)) -> 42 | K18: 3 | L18: =IF(J18<=K18,"🔴 REORDER","✅ OK") -> ✅ OK
A19: Air Conditioners | B19: =SUMIF(Sales!E4:E53,"P013",Sales!G4:G53)+SUMIF(Sales!E4:E53,"P014",Sales!G4:G53) -> 4 | C19: =SUMIF(Sales!E4:E53,"P013",Sales!K4:K53)+SUMIF(Sales!E4:E53,"P014",Sales!K4:K53) -> 356650 | D19: =C19/SUM(Sales!K4:K53) -> 0.026053252 | G19: Sony Bravia 43" | J19: =INDEX(Inventory!G4:G28,MATCH("P005",Inventory!A4:A28,0)) -> 13 | K19: 3 | L19: =IF(J19<=K19,"🔴 REORDER","✅ OK") -> ✅ OK
A20: Refrigerators | B20: =SUMIF(Sales!E4:E53,"P015",Sales!G4:G53)+SUMIF(Sales!E4:E53,"P016",Sales!G4:G53) -> 15 | C20: =SUMIF(Sales!E4:E53,"P015",Sales!K4:K53)+SUMIF(Sales!E4:E53,"P016",Sales!K4:K53) -> 1358280 | D20: =C20/SUM(Sales!K4:K53) -> 0.099222238 | G20: LG 32" Full HD | J20: =INDEX(Inventory!G4:G28,MATCH("P006",Inventory!A4:A28,0)) -> 14 | K20: 5 | L20: =IF(J20<=K20,"🔴 REORDER","✅ OK") -> ✅ OK
A21: Headphones | B21: =SUMIF(Sales!E4:E53,"P017",Sales!G4:G53)+SUMIF(Sales!E4:E53,"P018",Sales!G4:G53) -> 11 | C21: =SUMIF(Sales!E4:E53,"P017",Sales!K4:K53)+SUMIF(Sales!E4:E53,"P018",Sales!K4:K53) -> 285070 | D21: =C21/SUM(Sales!K4:K53) -> 0.020824339 | G21: Dell Inspiron 15 | J21: =INDEX(Inventory!G4:G28,MATCH("P007",Inventory!A4:A28,0)) -> 2 | K21: 4 | L21: =IF(J21<=K21,"🔴 REORDER","✅ OK") -> 🔴 REORDER
A22: Networking | B22: =SUMIF(Sales!E4:E53,"P019",Sales!G4:G53)+SUMIF(Sales!E4:E53,"P020",Sales!G4:G53) -> 6 | C22: =SUMIF(Sales!E4:E53,"P019",Sales!K4:K53)+SUMIF(Sales!E4:E53,"P020",Sales!K4:K53) -> 63580 | D22: =C22/SUM(Sales!K4:K53) -> 0.0046445135 | G22: HP Pavilion 14 | J22: =INDEX(Inventory!G4:G28,MATCH("P008",Inventory!A4:A28,0)) -> 41 | K22: 4 | L22: =IF(J22<=K22,"🔴 REORDER","✅ OK") -> ✅ OK
A23: Accessories | B23: =SUMIF(Sales!E4:E53,"P021",Sales!G4:G53)+SUMIF(Sales!E4:E53,"P022",Sales!G4:G53) -> 11 | C23: =SUMIF(Sales!E4:E53,"P021",Sales!K4:K53)+SUMIF(Sales!E4:E53,"P022",Sales!K4:K53) -> 220920 | D23: =C23/SUM(Sales!K4:K53) -> 0.016138187 | G23: Lenovo IdeaPad 5 | J23: =INDEX(Inventory!G4:G28,MATCH("P009",Inventory!A4:A28,0)) -> 48 | K23: 5 | L23: =IF(J23<=K23,"🔴 REORDER","✅ OK") -> ✅ OK
A24: Storage | B24: =SUMIF(Sales!E4:E53,"P023",Sales!G4:G53)+SUMIF(Sales!E4:E53,"P024",Sales!G4:G53) -> 10 | C24: =SUMIF(Sales!E4:E53,"P023",Sales!K4:K53)+SUMIF(Sales!E4:E53,"P024",Sales!K4:K53) -> 238750 | D24: =C24/SUM(Sales!K4:K53) -> 0.017440667 | G24: MacBook Air M2 | J24: =INDEX(Inventory!G4:G28,MATCH("P010",Inventory!A4:A28,0)) -> 8 | K24: 2 | L24: =IF(J24<=K24,"🔴 REORDER","✅ OK") -> ✅ OK
A25: Cameras | B25: =SUMIF(Sales!E4:E53,"P025",Sales!G4:G53) -> 4 | C25: =SUMIF(Sales!E4:E53,"P025",Sales!K4:K53) -> 601600 | D25: =C25/SUM(Sales!K4:K53) -> 0.043946828 | G25: Samsung Galaxy Tab S9 | J25: =INDEX(Inventory!G4:G28,MATCH("P011",Inventory!A4:A28,0)) -> 41 | K25: 3 | L25: =IF(J25<=K25,"🔴 REORDER","✅ OK") -> ✅ OK
G26: iPad Air 5th Gen | J26: =INDEX(Inventory!G4:G28,MATCH("P012",Inventory!A4:A28,0)) -> 37 | K26: 3 | L26: =IF(J26<=K26,"🔴 REORDER","✅ OK") -> ✅ OK
G27: Samsung 1.5 Ton AC | J27: =INDEX(Inventory!G4:G28,MATCH("P013",Inventory!A4:A28,0)) -> 27 | K27: 3 | L27: =IF(J27<=K27,"🔴 REORDER","✅ OK") -> ✅ OK
A28: 🏆 TOP CUSTOMERS BY REVENUE | G28: Haier 1 Ton AC | J28: =INDEX(Inventory!G4:G28,MATCH("P014",Inventory!A4:A28,0)) -> 16 | K28: 4 | L28: =IF(J28<=K28,"🔴 REORDER","✅ OK") -> ✅ OK
A29: Customer ID | B29: Customer Name | D29: Total Revenue | E29: Orders | G29: Dawlance Refrigerator | J29: =INDEX(Inventory!G4:G28,MATCH("P015",Inventory!A4:A28,0)) -> 36 | K29: 3 | L29: =IF(J29<=K29,"🔴 REORDER","✅ OK") -> ✅ OK
A30: C001 | B30: Ahmed Enterprises | D30: =SUMIF(Sales!C4:C53,"C001",Sales!K4:K53) -> 2189650 | E30: =COUNTIF(Sales!C4:C53,"C001") -> 5 | G30: PEL Refrigerator | J30: =INDEX(Inventory!G4:G28,MATCH("P016",Inventory!A4:A28,0)) -> 49 | K30: 4 | L30: =IF(J30<=K30,"🔴 REORDER","✅ OK") -> ✅ OK
A31: C002 | B31: Fatima Khan | D31: =SUMIF(Sales!C4:C53,"C002",Sales!K4:K53) -> 1251410 | E31: =COUNTIF(Sales!C4:C53,"C002") -> 5 | G31: Sony WH-1000XM5 | J31: =INDEX(Inventory!G4:G28,MATCH("P017",Inventory!A4:A28,0)) -> 19 | K31: 8 | L31: =IF(J31<=K31,"🔴 REORDER","✅ OK") -> ✅ OK
A32: C003 | B32: Tech Solutions Pvt | D32: =SUMIF(Sales!C4:C53,"C003",Sales!K4:K53) -> 581150 | E32: =COUNTIF(Sales!C4:C53,"C003") -> 3 | G32: JBL Tune 770NC | J32: =INDEX(Inventory!G4:G28,MATCH("P018",Inventory!A4:A28,0)) -> 23 | K32: 10 | L32: =IF(J32<=K32,"🔴 REORDER","✅ OK") -> ✅ OK
A33: C004 | B33: Usman Ali | D33: =SUMIF(Sales!C4:C53,"C004",Sales!K4:K53) -> 174440 | E33: =COUNTIF(Sales!C4:C53,"C004") -> 2 | G33: TP-Link WiFi Router | J33: =INDEX(Inventory!G4:G28,MATCH("P019",Inventory!A4:A28,0)) -> 39 | K33: 15 | L33: =IF(J33<=K33,"🔴 REORDER","✅ OK") -> ✅ OK
A34: C005 | B34: Digital World Store | D34: =SUMIF(Sales!C4:C53,"C005",Sales!K4:K53) -> 1167100 | E34: =COUNTIF(Sales!C4:C53,"C005") -> 6 | G34: Huawei WiFi 6 Router | J34: =INDEX(Inventory!G4:G28,MATCH("P020",Inventory!A4:A28,0)) -> 26 | K34: 10 | L34: =IF(J34<=K34,"🔴 REORDER","✅ OK") -> ✅ OK
A35: C006 | B35: Sara Malik | D35: =SUMIF(Sales!C4:C53,"C006",Sales!K4:K53) -> 705600 | E35: =COUNTIF(Sales!C4:C53,"C006") -> 1 | G35: Logitech MX Master 3 | J35: =INDEX(Inventory!G4:G28,MATCH("P021",Inventory!A4:A28,0)) -> 30 | K35: 12 | L35: =IF(J35<=K35,"🔴 REORDER","✅ OK") -> ✅ OK
A36: C007 | B36: Bilal Electronics | D36: =SUMIF(Sales!C4:C53,"C007",Sales!K4:K53) -> 432000 | E36: =COUNTIF(Sales!C4:C53,"C007") -> 1 | G36: Apple Magic Mouse | J36: =INDEX(Inventory!G4:G28,MATCH("P022",Inventory!A4:A28,0)) -> 29 | K36: 8 | L36: =IF(J36<=K36,"🔴 REORDER","✅ OK") -> ✅ OK
A37: C008 | B37: Zara Iqbal | D37: =SUMIF(Sales!C4:C53,"C008",Sales!K4:K53) -> 306730 | E37: =COUNTIF(Sales!C4:C53,"C008") -> 4 | G37: Samsung 1TB SSD | J37: =INDEX(Inventory!G4:G28,MATCH("P023",Inventory!A4:A28,0)) -> 8 | K37: 10 | L37: =IF(J37<=K37,"🔴 REORDER","✅ OK") -> 🔴 REORDER
G38: Western Digital 2TB HDD | J38: =INDEX(Inventory!G4:G28,MATCH("P024",Inventory!A4:A28,0)) -> 38 | K38: 10 | L38: =IF(J38<=K38,"🔴 REORDER","✅ OK") -> ✅ OK
G39: Canon EOS R50 | J39: =INDEX(Inventory!G4:G28,MATCH("P025",Inventory!A4:A28,0)) -> 31 | K39: 2 | L39: =IF(J39<=K39,"🔴 REORDER","✅ OK") -> ✅ OK
G43: 💰 CASH vs CREDIT SALES BREAKDOWN
G44: Payment Mode | I44: # Sales | J44: Revenue | L44: Share %
G45: Cash | I45: =COUNTIF(Sales!L4:L53,"Cash") -> 10 | J45: =SUMIF(Sales!L4:L53,"Cash",Sales!K4:K53) -> 2947860 | L45: =J45/SUM(Sales!K4:K53) -> 0.21534092
G46: Credit | I46: =COUNTIF(Sales!L4:L53,"Credit") -> 15 | J46: =SUMIF(Sales!L4:L53,"Credit",Sales!K4:K53) -> 4984430 | L46: =J46/SUM(Sales!K4:K53) -> 0.36411218
G47: Bank Transfer | I47: =COUNTIF(Sales!L4:L53,"Bank Transfer") -> 13 | J47: =SUMIF(Sales!L4:L53,"Bank Transfer",Sales!K4:K53) -> 3557400 | L47: =J47/SUM(Sales!K4:K53) -> 0.25986777
...

Sheet Customers
A1: 👥 CUSTOMER MASTER DATABASE
A2: Customer Information & Credit Limits
A3: Customer ID | B3: Customer Name | C3: Phone | D3: Email | E3: Address | F3: City | G3: Customer Type | H3: Credit Limit | I3: Status
A4: C001 | B4: Ahmed Enterprises | C4: 0300-1111111 | D4: ahmed@ent.com | E4: Shop 5, Saddar | F4: Karachi | G4: Business | H4: 500000 | I4: Active
A5: C002 | B5: Fatima Khan | C5: 0321-2222222 | D5: fatima.k@gmail.com | E5: House 12, DHA | F5: Lahore | G5: Individual | H5: 100000 | I5: Active
A6: C003 | B6: Tech Solutions Pvt | C6: 0311-3333333 | D6: info@techsol.pk | E6: Office 3, I-8 | F6: Islamabad | G6: Business | H6: 750000 | I6: Active
A7: C004 | B7: Usman Ali | C7: 0333-4444444 | D7: usman.ali@yahoo.com | E7: Flat 8, Clifton | F7: Karachi | G7: Individual | H7: 75000 | I7: Active
A8: C005 | B8: Digital World Store | C8: 0345-5555555 | D8: dw@digitalworld.pk | E8: Main Market | F8: Lahore | G8: Business | H8: 600000 | I8: Active
A9: C006 | B9: Sara Malik | C9: 0312-6666666 | D9: sara.malik@gmail.com | E9: House 45, F-7 | F9: Islamabad | G9: Individual | H9: 50000 | I9: Active
A10: C007 | B10: Bilal Electronics | C10: 0322-7777777 | D10: bilal@electronics.pk | E10: Hafeez Centre | F10: Lahore | G10: Business | H10: 400000 | I10: Active
A11: C008 | B11: Zara Iqbal | C11: 0334-8888888 | D11: zara.iq@gmail.com | E11: House 22, PECHS | F11: Karachi | G11: Individual | H11: 80000 | I11: Active
A12: C009 | B12: NextGen Computers | C12: 0315-9999999 | D12: ng@nextgen.pk | E12: Gulshan-e-Iqbal | F12: Karachi | G12: Business | H12: 550000 | I12: Active
A13: C010 | B13: Kamran Mirza | C13: 0316-0000000 | D13: k.mirza@hotmail.com | E13: House 7, Model Town | F13: Lahore | G13: Individual | H13: 60000 | I13: Active
A14: C011 | B14: Karachi Computer Shop | C14: 0317-1212121 | D14: kcs@kcs.pk | E14: Raja Ghazanfar | F14: Karachi | G14: Business | H14: 450000 | I14: Active
A15: C012 | B15: Nadia Hussain | C15: 0318-3434343 | D15: nadia.h@gmail.com | E15: Flat 3, Gulberg | F15: Lahore | G15: Individual | H15: 90000 | I15: Active
... A18: C015 | B18: Pixel Perfect Store | C18: 0323-9090909 | D18: pp@pixel.pk | E18: Liberty Market | F18: Lahore | G18: Business | H18: 500000 | I18: Active

Sheet Purchases
A1: 📥 PURCHASE ENTRY (Stock In)
A2: Record all supplier purchases — auto-linked to inventory
A3: Purchase ID | B3: Date | C3: Supplier ID | D3: Supplier Name | E3: Product ID | F3: Product Name | G3: Qty | H3: Unit Cost | I3: Total Cost | J3: Payment Mode | K3: Invoice Ref | L3: Status
A4: PUR0001 | B4: 45619 | C4: SUP002 | D4: Apple Authorized Dist. | E4: P001 | F4: Samsung Galaxy S24 | G4: 12 | H4: 85000 | I4: 1020000 | J4: Bank Transfer | K4: INV-42098 | L4: Received
A5: PUR0002 | B5: 45406 | C5: SUP003 | D5: Xiaomi Pakistan | E5: P024 | F5: Western Digital 2TB HDD | G5: 2 | H5: 12000 | I5: 24000 | J5: Credit | K5: INV-81482 | L5: Received
A6: PUR0003 | B6: 45336 | C6: SUP010 | D6: JBL Audio Pakistan | E6: P014 | F6: Haier 1 Ton AC | G6: 1 | H6: 65000 | I6: 65000 | J6: Cash | K6: INV-22280 | L6: Received
A7: PUR0004 | B7: 45403 | C7: SUP004 | D7: Sony Pakistan | E7: P017 | F7: Sony WH-1000XM5 | G7: 10 | H7: 32000 | I7: 320000 | J7: Cash | K7: INV-83563 | L7: Received
A8: PUR0005 | B8: 45393 | C8: SUP012 | D8: Huawei Pakistan | E8: P021 | F8: Logitech MX Master 3 | G8: 12 | H8: 12000 | I8: 144000 | J8: Credit | K8: INV-64987 | L8: Received
A9: PUR0006 | B9: 45404 | C9: SUP008 | D9: Haier Pakistan | E9: P019 | F9: TP-Link WiFi Router | G9: 5 | H9: 5500 | I9: 27500 | J9: Cash | K9: INV-30926 | L9: Received
A10: PUR0007 | B10: 45649 | C10: SUP007 | D10: Lenovo Distributor | E10: P011 | F10: Samsung Galaxy Tab S9 | G10: 5 | H10: 95000 | I10: 475000 | J10: Cash | K10: INV-38221 | L10: Received
A11: PUR0008 | B11: 45464 | C11: SUP002 | D11: Apple Authorized Dist. | E11: P003 | F11: Xiaomi Redmi Note 13 | G11: 7 | H11: 35000 | I11: 245000 | J11: Cash | K11: INV-57052 | L11: Received
A12: PUR0009 | B12: 45468 | C12: SUP010 | D12: JBL Audio Pakistan | E12: P009 | F12: Lenovo IdeaPad 5 | G12: 13 | H12: 68000 | I12: 884000 | J12: Cash | K12: INV-70217 | L12: Received
A13: PUR0010 | B13: 45566 | C13: SUP002 | D13: Apple Authorized Dist. | E13: P013 | F13: Samsung 1.5 Ton AC | G13: 2 | H13: 88000 | I13: 176000 | J13: Credit | K13: INV-48427 | L13: Received
A14: PUR0011 | B14: 45613 | C14: SUP010 | D14: JBL Audio Pakistan | E14: P012 | F14: iPad Air 5th Gen | G14: 10 | H14: 120000 | I14: 1200000 | J14: Cash | K14: INV-19116 | L14: Received
A15: PUR0012 | B15: 45315 | C15: SUP011 | D15: TP-Link Pakistan | E15: P008 | F15: HP Pavilion 14 | G15: 13 | H15: 72000 | I15: 936000 | J15: Bank Transfer | K15: INV-20458 | L15: Received
... A53: PUR0050 | B53: 45636 | C53: SUP011 | D53: TP-Link Pakistan | E53: P021 | F53: Logitech MX Master 3 | G53: 2 | H53: 12000 | I53: 24000 | J53: Cash | K53: INV-62772 | L53: Received
A54: TOTAL PURCHASES | I54: =SUM(I4:I53) -> 26453500

Sheet Sales
A1: 📤 SALES ENTRY (Stock Out)
A2: Record all customer sales — auto-linked to inventory & receivables
A3: Invoice ID | B3: Date | C3: Customer ID | D3: Customer Name | E3: Product ID | F3: Product Name | G3: Qty | H3: Unit Price | I3: Discount% | J3: Net Price | K3: Total | L3: Payment Mode | M3: Amount Paid | N3: Balance Due
A4: INV0001 | B4: 45465 | C4: C013 | D4: Smart Tech Hub | E4: P004 | F4: Samsung 55" 4K TV | G4: 2 | H4: 125000 | I4: 0.02 | J4: 122500 | K4: 245000 | L4: Credit | M4: 245000 | N4: 0
A5: INV0002 | B5: 45521 | C5: C003 | D5: Tech Solutions Pvt | E5: P014 | F5: Haier 1 Ton AC | G5: 2 | H5: 85000 | I5: 0.03 | J5: 82450 | K5: 164900 | L5: Installment | M5: 82450 | N5: 82450
A6: INV0003 | B6: 45330 | C6: C008 | D6: Zara Iqbal | E6: P018 | F6: JBL Tune 770NC | G6: 1 | H6: 26000 | I6: 0 | J6: 26000 | K6: 26000 | L6: Cash | M6: 26000 | N6: 0
A7: INV0004 | B7: 45339 | C7: C015 | D7: Pixel Perfect Store | E7: P025 | F7: Canon EOS R50 | G7: 2 | H7: 160000 | I7: 0.02 | J7: 156800 | K7: 313600 | L7: Installment | M7: 219520 | N7: 94080
A8: INV0005 | B8: 45538 | C8: C004 | D8: Usman Ali | E8: P013 | F8: Samsung 1.5 Ton AC | G8: 1 | H8: 115000 | I8: 0.02 | J8: 112700 | K8: 112700 | L8: Installment | M8: 0 | N8: 112700
A9: INV0006 | B9: 45491 | C9: C005 | D9: Digital World Store | E9: P015 | F9: Dawlance Refrigerator | G9: 3 | H9: 98000 | I9: 0.05 | J9: 93100 | K9: 279300 | L9: Installment | M9: 139650 | N9: 139650
A10: INV0007 | B10: 45389 | C10: C005 | D10: Digital World Store | E10: P007 | F10: Dell Inspiron 15 | G10: 1 | H10: 99000 | I10: 0.07 | J10: 92070 | K10: 92070 | L10: Cash | M10: 92070 | N10: 0
A11: INV0008 | B11: 45452 | C11: C001 | D11: Ahmed Enterprises | E11: P002 | F11: iPhone 15 Pro | G11: 5 | H11: 240000 | I11: 0.05 | J11: 228000 | K11: 1140000 | L11: Credit | M11: 0 | N11: 1140000
A12: INV0009 | B12: 45552 | C12: C002 | D12: Fatima Khan | E12: P006 | F12: LG 32" Full HD | G12: 1 | H12: 58000 | I12: 0.07 | J12: 53940 | K12: 53940 | L12: Cash | M12: 53940 | N12: 0
A13: INV0010 | B13: 45637 | C13: C014 | D13: Rizwan Ahmad | E13: P008 | F13: HP Pavilion 14 | G13: 4 | H13: 92000 | I13: 0 | J13: 92000 | K13: 368000 | L13: Credit | M13: 368000 | N13: 0
A14: INV0011 | B14: 45596 | C14: C001 | D14: Ahmed Enterprises | E14: P020 | F14: Huawei WiFi 6 Router | G14: 1 | H14: 11000 | I14: 0.05 | J14: 10450 | K14: 10450 | L14: Bank Transfer | M14: 10450 | N14: 0
A15: INV0012 | B15: 45425 | C15: C004 | D15: Usman Ali | E15: P022 | F15: Apple Magic Mouse | G15: 3 | H15: 21000 | I15: 0.02 | J15: 20580 | K15: 61740 | L15: Bank Transfer | M15: 61740 | N15: 0
... A53: INV0050 | B53: 45382 | C53: C013 | D53: Smart Tech Hub | E53: P023 | F53: Samsung 1TB SSD | G53: 5 | H53: 25000 | I53: 0.05 | J53: 23750 | K53: 118750 | L53: Cash | M53: 118750 | N53: 0
A54: TOTAL SALES | K54: =SUM(K4:K53) -> 13689270 | M54: =SUM(M4:M53) -> 9805079 | N54: =SUM(N4:N53) -> 3884191

Sheet Inventory
A1: 🏪 INVENTORY STATUS (Auto-Calculated)
A2: Real-time stock levels, FIFO valuation & low-stock alerts
A3: Product ID | B3: Product Name | C3: Category | D3: Opening Stock | E3: Total Purchased | F3: Total Sold | G3: Current Stock | H3: Reorder Level | I3: Status | J3: Cost Price | K3: FIFO Value | L3: Stock Alert
A4: P001 | B4: Samsung Galaxy S24 | C4: Mobile Phones | D4: 22 | E4: =SUMIF(Purchases!E:E,Inventory!A4,Purchases!G:G) -> 23 | F4: =SUMIF(Sales!E:E,Inventory!A4,Sales!G:G) -> 0 | G4: =D4+E4-F4 -> 45 | H4: 5 | I4: =IF(G4<=0,"⛔ Out of Stock",IF(G4<=H4,"⚠️ Low Stock","✅ In Stock")) -> ✅ In Stock | J4: 85000 | K4: =G4*J4 -> 3825000 | L4: =IF(G4<=H4,"🔴 REORDER NOW","")
A5: P002 | B5: iPhone 15 Pro | C5: Mobile Phones | D5: 12 | E5: =SUMIF(Purchases!E:E,Inventory!A5,Purchases!G:G) -> 18 | F5: =SUMIF(Sales!E:E,Inventory!A5,Sales!G:G) -> 12 | G5: =D5+E5-F5 -> 18 | H5: 3 | I5: =IF(G5<=0,"⛔ Out of Stock",IF(G5<=H5,"⚠️ Low Stock","✅ In Stock")) -> ✅ In Stock | J5: 195000 | K5: =G5*J5 -> 3510000 | L5: =IF(G5<=H5,"🔴 REORDER NOW","")
A6: P003 | B6: Xiaomi Redmi Note 13 | C6: Mobile Phones | D6: 8 | E6: =SUMIF(Purchases!E:E,Inventory!A6,Purchases!G:G) -> 7 | F6: =SUMIF(Sales!E:E,Inventory!A6,Sales!G:G) -> 5 | G6: =D6+E6-F6 -> 10 | H6: 10 | I6: =IF(G6<=0,"⛔ Out of Stock",IF(G6<=H6,"⚠️ Low Stock","✅ In Stock")) -> ⚠️ Low Stock | J6: 35000 | K6: =G6*J6 -> 350000 | L6: =IF(G6<=H6,"🔴 REORDER NOW","") -> 🔴 REORDER NOW
A7: P004 | B7: Samsung 55" 4K TV | C7: Televisions | D7: 19 | E7: =SUMIF(Purchases!E:E,Inventory!A7,Purchases!G:G) -> 32 | F7: =SUMIF(Sales!E:E,Inventory!A7,Sales!G:G) -> 9 | G7: =D7+E7-F7 -> 42 | H7: 3 | I7: =IF(G7<=0,"⛔ Out of Stock",IF(G7<=H7,"⚠️ Low Stock","✅ In Stock")) -> ✅ In Stock | J7: 95000 | K7: =G7*J7 -> 3990000 | L7: =IF(G7<=H7,"🔴 REORDER NOW","")
A8: P005 | B8: Sony Bravia 43" | C8: Televisions | D8: 9 | E8: =SUMIF(Purchases!E:E,Inventory!A8,Purchases!G:G) -> 4 | F8: =SUMIF(Sales!E:E,Inventory!A8,Sales!G:G) -> 0 | G8: =D8+E8-F8 -> 13 | H8: 3 | I8: =IF(G8<=0,"⛔ Out of Stock",IF(G8<=H8,"⚠️ Low Stock","✅ In Stock")) -> ✅ In Stock | J8: 85000 | K8: =G8*J8 -> 1105000 | L8: =IF(G8<=H8,"🔴 REORDER NOW","")
A9: P006 | B9: LG 32" Full HD | C9: Televisions | D9: 19 | E9: =SUMIF(Purchases!E:E,Inventory!A9,Purchases!G:G) -> 0 | F9: =SUMIF(Sales!E:E,Inventory!A9,Sales!G:G) -> 5 | G9: =D9+E9-F9 -> 14 | H9: 5 | I9: =IF(G9<=0,"⛔ Out of Stock",IF(G9<=H9,"⚠️ Low Stock","✅ In Stock")) -> ✅ In Stock | J9: 42000 | K9: =G9*J9 -> 588000 | L9: =IF(G9<=H9,"🔴 REORDER NOW","")
A10: P007 | B10: Dell Inspiron 15 | C10: Laptops | D10: 21 | E10: =SUMIF(Purchases!E:E,Inventory!A10,Purchases!G:G) -> 0 | F10: =SUMIF(Sales!E:E,Inventory!A10,Sales!G:G) -> 19 | G10: =D10+E10-F10 -> 2 | H10: 4 | I10: =IF(G10<=0,"⛔ Out of Stock",IF(G10<=H10,"⚠️ Low Stock","✅ In Stock")) -> ⚠️ Low Stock | J10: 78000 | K10: =G10*J10 -> 156000 | L10: =IF(G10<=H10,"🔴 REORDER NOW","") -> 🔴 REORDER NOW
A11: P008 | B11: HP Pavilion 14 | C11: Laptops | D11: 22 | E11: =SUMIF(Purchases!E:E,Inventory!A11,Purchases!G:G) -> 28 | F11: =SUMIF(Sales!E:E,Inventory!A11,Sales!G:G) -> 9 | G11: =D11+E11-F11 -> 41 | H11: 4 | I11: =IF(G11<=0,"⛔ Out of Stock",IF(G11<=H11,"⚠️ Low Stock","✅ In Stock")) -> ✅ In Stock | J11: 72000 | K11: =G11*J11 -> 2952000 | L11: =IF(G11<=H11,"🔴 REORDER NOW","")
A12: P009 | B12: Lenovo IdeaPad 5 | C12: Laptops | D12: 24 | E12: =SUMIF(Purchases!E:E,Inventory!A12,Purchases!G:G) -> 25 | F12: =SUMIF(Sales!E:E,Inventory!A12,Sales!G:G) -> 1 | G12: =D12+E12-F12 -> 48 | H12: 5 | I12: =IF(G12<=0,"⛔ Out of Stock",IF(G12<=H12,"⚠️ Low Stock","✅ In Stock")) -> ✅ In Stock | J12: 68000 | K12: =G12*J12 -> 3264000 | L12: =IF(G12<=H12,"🔴 REORDER NOW","")
A13: P010 | B13: MacBook Air M2 | C13: Laptops | D13: 15 | E13: =SUMIF(Purchases!E:E,Inventory!A13,Purchases!G:G) -> 7 | F13: =SUMIF(Sales!E:E,Inventory!A13,Sales!G:G) -> 14 | G13: =D13+E13-F13 -> 8 | H13: 2 | I13: =IF(G13<=0,"⛔ Out of Stock",IF(G13<=H13,"⚠️ Low Stock","✅ In Stock")) -> ✅ In Stock | J13: 185000 | K13: =G13*J13 -> 1480000 | L13: =IF(G13<=H13,"🔴 REORDER NOW","")
A14: P011 | B14: Samsung Galaxy Tab S9 | C14: Tablets | D14: 19 | E14: =SUMIF(Purchases!E:E,Inventory!A14,Purchases!G:G) -> 28 | F14: =SUMIF(Sales!E:E,Inventory!A14,Sales!G:G) -> 6 | G14: =D14+E14-F14 -> 41 | H14: 3 | I14: =IF(G14<=0,"⛔ Out of Stock",IF(G14<=H14,"⚠️ Low Stock","✅ In Stock")) -> ✅ In Stock | J14: 95000 | K14: =G14*J14 -> 3895000 | L14: =IF(G14<=H14,"🔴 REORDER NOW","")
A15: P012 | B15: iPad Air 5th Gen | C15: Tablets | D15: 24 | E15: =SUMIF(Purchases!E:E,Inventory!A15,Purchases!G:G) -> 13 | F15: =SUMIF(Sales!E:E,Inventory!A15,Sales!G:G) -> 0 | G15: =D15+E15-F15 -> 37 | H15: 3 | I15: =IF(G15<=0,"⛔ Out of Stock",IF(G15<=H15,"⚠️ Low Stock","✅ In Stock")) -> ✅ In Stock | J15: 120000 | K15: =G15*J15 -> 4440000 | L15: =IF(G15<=H15,"🔴 REORDER NOW","")
... A28: P025 | B28: Canon EOS R50 | C28: Cameras | D28: 20 | E28: =SUMIF(Purchases!E:E,Inventory!A28,Purchases!G:G) -> 15 | F28: =SUMIF(Sales!E:E,Inventory!A28,Sales!G:G) -> 4 | G28: =D28+E28-F28 -> 31 | H28: 2 | I28: =IF(G28<=0,"⛔ Out of Stock",IF(G28<=H28,"⚠️ Low Stock","✅ In Stock")) -> ✅ In Stock | J28: 125000 | K28: =G28*J28 -> 3875000 | L28: =IF(G28<=H28,"🔴 REORDER NOW","")
A29: TOTAL INVENTORY VALUE (FIFO) | K29: =SUM(K4:K28) -> 45410500

Sheet Expenses
A1: 💸 EXPENSE TRACKER
A2: Monthly operating expenses for net profit calculation
A3: Exp ID | B3: Date | C3: Category | D3: Description | E3: Amount | F3: Payment Mode | G3: Reference
A4: E001 | B4: 45517 | C4: Marketing | D4: Social media ads | E4: 28998 | F4: Cheque | G4: EXP-2269
A5: E002 | B5: 45431 | C5: Logistics | D5: Delivery & transport | E5: 8841 | F5: Bank Transfer | G5: EXP-6502
A6: E003 | B6: 45369 | C6: Salaries | D6: Staff salaries | E6: 159068 | F6: Bank Transfer | G6: EXP-4788
A7: E004 | B7: 45401 | C7: Utilities | D7: Electricity & internet bill | E7: 26573 | F7: Bank Transfer | G7: EXP-2052
A8: E005 | B8: 45569 | C8: Miscellaneous | D8: Petty cash expenses | E8: 4710 | F8: Bank Transfer | G8: EXP-8633
A9: E006 | B9: 45507 | C9: Rent | D9: Monthly shop rent | E9: 80000 | F9: Cheque | G9: EXP-7381
A10: E007 | B10: 45536 | C10: Rent | D10: Monthly shop rent | E10: 80000 | F10: Bank Transfer | G10: EXP-1096
A11: E008 | B11: 45506 | C11: Logistics | D11: Delivery & transport | E11: 11389 | F11: Cheque | G11: EXP-9818
A12: E009 | B12: 45404 | C12: Marketing | D12: Social media ads | E12: 35998 | F12: Bank Transfer | G12: EXP-5471
A13: E010 | B13: 45491 | C13: Office Supplies | D13: Stationery & supplies | E13: 2237 | F13: Cheque | G13: EXP-6507
A14: E011 | B14: 45376 | C14: Miscellaneous | D14: Petty cash expenses | E14: 7932 | F14: Cash | G14: EXP-8657
A15: E012 | B15: 45595 | C15: Rent | D15: Monthly shop rent | E15: 80000 | F15: Cash | G15: EXP-1444
... A53: E050 | B53: 45497 | C53: Salaries | D53: Staff salaries | E53: 154282 | F53: Cash | G53: EXP-9056
A54: TOTAL EXPENSES | E54: =SUM(E4:E53) -> 2188280

Sheet Receivables
A1: 💳 CUSTOMER RECEIVABLES (Credit Sales)
A2: Outstanding balances from credit customers
A3: Invoice ID | B3: Date | C3: Customer ID | D3: Customer Name | E3: Total Invoice | F3: Amount Paid | G3: Balance Due | H3: Due Date | I3: Status
A4: INV0002 | B4: 45521 | C4: C003 | D4: Tech Solutions Pvt | E4: 164900 | F4: 82450 | G4: 82450 | H4: 45551 | I4: Overdue
A5: INV0004 | B5: 45339 | C5: C015 | D5: Pixel Perfect Store | E5: 313600 | F5: 219520 | G5: 94080 | H5: 45369 | I5: Overdue
A6: INV0005 | B6: 45538 | C6: C004 | D6: Usman Ali | E6: 112700 | F6: 0 | G6: 112700 | H6: 45568 | I6: Overdue
A7: INV0006 | B7: 45491 | C7: C005 | D7: Digital World Store | E7: 279300 | F7: 139650 | G7: 139650 | H7: 45521 | I7: Overdue
A8: INV0008 | B8: 45452 | C8: C001 | D8: Ahmed Enterprises | E8: 1140000 | F8: 0 | G8: 1140000 | H8: 45482 | I8: Overdue
A9: INV0015 | B9: 45329 | C9: C009 | D9: NextGen Computers | E9: 480150 | F9: 144045 | G9: 336105 | H9: 45359 | I9: Overdue
A10: INV0016 | B10: 45327 | C10: C015 | D10: Pixel Perfect Store | E10: 267720 | F10: 187404 | G10: 80316 | H10: 45357 | I10: Overdue
A11: INV0019 | B11: 45360 | C11: C005 | D11: Digital World Store | E11: 112500 | F11: 33750 | G11: 78750 | H11: 45390 | I11: Overdue
A12: INV0021 | B12: 45550 | C12: C008 | D12: Zara Iqbal | E12: 88000 | F12: 26400 | G12: 61600 | H12: 45580 | I12: Overdue
A13: INV0025 | B13: 45481 | C13: C010 | D13: Kamran Mirza | E13: 49400 | F13: 0 | G13: 49400 | H13: 45511 | I13: Overdue
A14: INV0026 | B14: 45449 | C14: C006 | D14: Sara Malik | E14: 705600 | F14: 0 | G14: 705600 | H14: 45479 | I14: Overdue
A15: INV0027 | B15: 45473 | C15: C013 | D15: Smart Tech Hub | E15: 96720 | F15: 48360 | G15: 48360 | H15: 45503 | I15: Overdue
... A25: INV0049 | B25: 45367 | C25: C011 | D25: Karachi Computer Shop | E25: 25000 | F25: 12500 | G25: 12500 | H25: 45397 | I25: Overdue
A26: TOTAL OUTSTANDING | E26: =SUM(E4:E25) -> 5988610 | F26: =SUM(F4:F25) -> 2104419 | G26: =SUM(G4:G25) -> 3884191

Sheet Payables
A1: 🏦 SUPPLIER PAYABLES
A2: Outstanding amounts owed to suppliers
A3: Purchase ID | B3: Date | C3: Supplier ID | D3: Supplier Name | E3: Total Purchase | F3: Amount Paid | G3: Balance Due | H3: Status
A4: PUR0002 | B4: 45406 | C4: SUP003 | D4: Xiaomi Pakistan | E4: 24000 | F4: 24000 | G4: 0 | H4: Paid
A5: PUR0005 | B5: 45393 | C5: SUP012 | D5: Huawei Pakistan | E5: 144000 | F5: 144000 | G5: 0 | H5: Paid
A6: PUR0010 | B6: 45566 | C6: SUP002 | D6: Apple Authorized Dist. | E6: 176000 | F6: 176000 | G6: 0 | H6: Paid
A7: PUR0015 | B7: 45399 | C7: SUP011 | D7: TP-Link Pakistan | E7: 816000 | F7: 0 | G7: 816000 | H7: Outstanding
A8: PUR0016 | B8: 45328 | C8: SUP010 | D8: JBL Audio Pakistan | E8: 36000 | F8: 0 | G8: 36000 | H8: Outstanding
A9: PUR0017 | B9: 45375 | C9: SUP008 | D9: Haier Pakistan | E9: 440000 | F9: 0 | G9: 440000 | H9: Outstanding
A10: PUR0020 | B10: 45400 | C10: SUP015 | D10: Canon Pakistan | E10: 82500 | F10: 82500 | G10: 0 | H10: Paid
A11: PUR0021 | B11: 45400 | C11: SUP011 | D11: TP-Link Pakistan | E11: 434000 | F11: 217000 | G11: 217000 | H11: Outstanding
A12: PUR0022 | B12: 45365 | C12: SUP005 | D12: LG Electronics | E12: 340000 | F12: 0 | G12: 340000 | H12: Outstanding
A13: PUR0024 | B13: 45496 | C13: SUP006 | D13: Dell & HP Distributor | E13: 216000 | F13: 0 | G13: 216000 | H13: Outstanding
A14: PUR0026 | B14: 45613 | C14: SUP003 | D14: Xiaomi Pakistan | E14: 105000 | F14: 0 | G14: 105000 | H14: Outstanding
A15: PUR0027 | B15: 45489 | C15: SUP007 | D15: Lenovo Distributor | E15: 60000 | F15: 60000 | G15: 0 | H15: Paid
... A25: PUR0049 | B25: 45508 | C25: SUP007 | D25: Lenovo Distributor | E25: 1050000 | F25: 525000 | G25: 525000 | H25: Outstanding
A26: TOTAL PAYABLES | E26: =SUM(E4:E25) -> 10586500 | F26: =SUM(F4:F25) -> 5862500 | G26: =SUM(G4:G25) -> 4724000

Sheet Profit Analysis
A1: 📊 PROFIT & LOSS ANALYSIS
A2: Gross Profit & Net Profit — auto-linked from all sheets
A4: REVENUE | C4: Amount (PKR) | D4: Currency
A5: Total Sales Revenue | C5: =SUM(Sales!K4:K53) -> 13689270 | D5: PKR
A6: Cash Sales | C6: =SUMIF(Sales!L4:L53,"Cash",Sales!K4:K53) -> 2947860 | D6: PKR
A7: Credit Sales | C7: =SUMIF(Sales!L4:L53,"Credit",Sales!K4:K53) -> 4984430 | D7: PKR
A8: Bank Transfer Sales | C8: =SUMIF(Sales!L4:L53,"Bank Transfer",Sales!K4:K53) -> 3557400 | D8: PKR
A10: COST OF GOODS SOLD (COGS)
A11: Total Cost of Purchases | C11: =SUM(Purchases!I4:I53) -> 26453500 | D11: PKR
A12: Opening Inventory Value | C12: =SUMPRODUCT(Inventory!D4:D28,Inventory!J4:J28) -> 30405000 | D12: PKR
A13: Closing Inventory Value (FIFO) | C13: =SUM(Inventory!K4:K28) -> 45410500 | D13: PKR
A14: NET COGS = Purchases + Opening − Closing | C14: =C11+C12-C13 -> 11448000 | D14: PKR
A16: GROSS PROFIT | C16: =C5-C14 -> 2241270
A17: Gross Profit Margin % | C17: =C16/C5 -> 0.16372458 | D17: PKR
A19: OPERATING EXPENSES
A20: Rent | C20: =SUMIF(Expenses!C4:C53,"Rent",Expenses!E4:E53) -> 640000 | D20: PKR
A21: Salaries | C21: =SUMIF(Expenses!C4:C53,"Salaries",Expenses!E4:E53) -> 1050485 | D21: PKR
A22: Utilities | C22: =SUMIF(Expenses!C4:C53,"Utilities",Expenses!E4:E53) -> 105248 | D22: PKR
A23: Marketing | C23: =SUMIF(Expenses!C4:C53,"Marketing",Expenses!E4:E53) -> 192623 | D23: PKR
A24: Logistics | C24: =SUMIF(Expenses!C4:C53,"Logistics",Expenses!E4:E53) -> 107514 | D24: PKR
A25: Repairs & Maintenance | C25: =SUMIF(Expenses!C4:C53,"Repairs & Maintenance",Expenses!E4:E53) -> 43666 | D25: PKR
A26: Miscellaneous | C26: =SUMIF(Expenses!C4:C53,"Miscellaneous",Expenses!E4:E53) -> 38291 | D26: PKR
A27: Office Supplies | C27: =SUMIF(Expenses!C4:C53,"Office Supplies",Expenses!E4:E53) -> 10453 | D27: PKR
A28: TOTAL OPERATING EXPENSES | C28: =SUM(C20:C27) -> 2188280 | D28: PKR
A30: NET PROFIT | C30: =C16-C28 -> 52990
A31: Net Profit Margin % | C31: =C30/C5 -> 0.003870915 | D31: PKR
A33: CASH FLOW INDICATORS
A34: Total Receivables Outstanding | C34: =SUM(Receivables!G4:G25) -> 3884191 | D34: PKR
A35: Total Payables Outstanding | C35: =SUM(Payables!G4:G25) -> 4724000 | D35: PKR
A36: Net Working Capital Position | C36: =C34-C35 -> -839809 | D36: PKR
